Workbook

Sheet Sheet1
A1: id | B1: gender | C1: age | D1: type | E1: location1 | F1: location2 | G1: dateexpose1 | H1: dateexpose2 | I1: dateonset | J1: datepositive | K1: datereport | L1: vaccine | M1: vaccine_type | N1: vaccinelastdate | O1: Throat_O | P1: Throat_N
A2: 9 | B2: Female | C2: 65 | D2: Asymptomatic | E2: 益阳 | F2: 赫山区 | G2: 44400 | H2: 44400 | I2: 44406 | J2: 44406 | K2: 44406 | L2: 1 | N2: 44405 | O2: =VLOOKUP(A2,Sheet2!C10:F144,4,FALSE) -> 23.61 | P2: =VLOOKUP(A2,Sheet2!C10:F144,4,FALSE) -> 23.61
A3: 17 | B3: Female | C3: 36 | D3: Moderate | E3: 张家界 | F3: 永定区 | G3: 44401 | H3: 44401 | I3: 44406 | J3: 44407 | K3: 44407 | L3: 1 | N3: 44405 | O3: =VLOOKUP(A3,Sheet2!C18:F152,4,FALSE) -> 21 | P3: =VLOOKUP(A3,Sheet2!C18:F152,4,FALSE) -> 21
A4: 40 | B4: Female | C4: 34 | D4: Asymptomatic | E4: 长沙 | F4: 天心区 | G4: 44402 | H4: 44402 | I4: 44409 | J4: 44409 | K4: 44409 | L4: 1 | M4: Sinovac | N4: 44404
A5: 47 | B5: Female | C5: 59 | D5: Moderate | E5: 湘潭 | F5: 雨湖区 | G5: 44401 | H5: 44401 | I5: 44407 | J5: 44410 | K5: 44410 | L5: 1 | M5: Sinovac | N5: 44403
A6: 3 | B6: Female | C6: 38 | D6: Moderate | E6: 张家界 | F6: 永定区 | G6: 44399 | H6: 44399 | I6: 44399 | J6: 44406 | K6: 44406 | L6: 1 | M6: Combind | N6: 44399
A7: 83 | B7: Female | C7: 28 | D7: Moderate | E7: 张家界 | F7: 永定区 | G7: 44405 | H7: 44405 | I7: 44410 | J7: 44413 | K7: 44413 | L7: 0 | M7: Sinopharm | N7: 44405 | O7: =VLOOKUP(A7,Sheet2!C84:F218,4,FALSE) -> 19.07 | P7: =VLOOKUP(A7,Sheet2!C84:F218,4,FALSE) -> 19.07
A8: 94 | B8: Female | C8: 39 | D8: Moderate | E8: 张家界 | F8: 永定区 | I8: 44415 | J8: 44416 | K8: 44416 | L8: 0 | M8: Sinovac | N8: 44404 | O8: =VLOOKUP(A8,Sheet2!C95:F229,4,FALSE) -> 25.58 | P8: =VLOOKUP(A8,Sheet2!C95:F229,4,FALSE) -> 25.58
A9: 73 | B9: Female | C9: 47 | D9: Mild | E9: 株洲 | F9: 荷塘区 | G9: 44404 | H9: 44404 | I9: 44412 | J9: 44412 | K9: 44412 | L9: 1 | M9: Sinovac | N9: 44399 | O9: =VLOOKUP(A9,Sheet2!C74:F208,4,FALSE) -> 29.2 | P9: =VLOOKUP(A9,Sheet2!C74:F208,4,FALSE) -> 29.2
A10: 118 | B10: Female | C10: 22 | D10: Moderate | E10: 张家界 | F10: 永定区 | I10: 44419 | J10: 44419 | K10: 44419 | L10: 1 | M10: Sinovac | N10: 44405 | O10: =VLOOKUP(A10,Sheet2!C119:F253,4,FALSE) -> 25.07 | P10: =VLOOKUP(A10,Sheet2!C119:F253,4,FALSE) -> 25.07
A11: 120 | B11: Male | C11: 59 | D11: Moderate | E11: 张家界 | F11: 永定区 | I11: 44419 | J11: 44419 | K11: 44419 | L11: 1 | M11: Sinovac | N11: 44405 | O11: =VLOOKUP(A11,Sheet2!C121:F255,4,FALSE) -> 16.74 | P11: =VLOOKUP(A11,Sheet2!C121:F255,4,FALSE) -> 16.74
A12: 54 | B12: Male | C12: 53 | D12: Asymptomatic | E12: 益阳 | F12: 赫山区 | G12: 44401 | H12: 44401 | I12: 44410 | J12: 44411 | K12: 44411 | L12: 2 | M12: Zhifei | N12: 44397 | O12: =VLOOKUP(A12,Sheet2!C55:F189,4,FALSE) -> 32.03 | P12: =VLOOKUP(A12,Sheet2!C55:F189,4,FALSE) -> 32.03
A13: 11 | B13: Female | C13: 29 | D13: Mild | E13: 株洲 | F13: 石峰区 | G13: 44401 | H13: 44401 | I13: 44407 | J13: 44407 | K13: 44407 | L13: 1 | M13: Sinopharm | N13: 44392 | O13: =VLOOKUP(A13,Sheet2!C12:F146,4,FALSE) -> 37.1 | P13: =VLOOKUP(A13,Sheet2!C12:F146,4,FALSE) -> 37.1
A14: 12 | B14: Female | C14: 40 | D14: Moderate | E14: 湘潭 | F14: 雨湖区 | G14: 44401 | H14: 44401 | I14: 44406 | J14: 44407 | K14: 44407 | L14: 1 | M14: Sinovac | N14: 44390
A15: 107 | B15: Female | C15: 47 | D15: Moderate | E15: 张家界 | F15: 永定区 | I15: 44417 | J15: 44417 | K15: 44417 | L15: 2 | M15: Sinovac | N15: 44399 | O15: =VLOOKUP(A15,Sheet2!C108:F242,4,FALSE) -> 28.41 | P15: =VLOOKUP(A15,Sheet2!C108:F242,4,FALSE) -> 28.41
A16: 69 | B16: Male | C16: 44 | D16: Moderate | E16: 株洲 | F16: 石峰区 | G16: 44405 | H16: 44405 | I16: 44411 | J16: 44412 | K16: 44412 | L16: 1 | M16: Sinopharm | N16: 44394 | O16: =VLOOKUP(A16,Sheet2!C70:F204,4,FALSE) -> 28.1 | P16: =VLOOKUP(A16,Sheet2!C70:F204,4,FALSE) -> 28.1
A17: 46 | B17: Male | C17: 18 | D17: Mild | E17: 株洲 | F17: 荷塘区 | G17: 44405 | H17: 44405 | I17: 44409 | J17: 44409 | K17: 44409 | L17: 0 | N17: 44390 | O17: =VLOOKUP(A17,Sheet2!C47:F181,4,FALSE) -> 31.2 | P17: =VLOOKUP(A17,Sheet2!C47:F181,4,FALSE) -> 31.2
A18: 67 | B18: Male | C18: 31 | D18: Moderate | E18: 株洲 | F18: 石峰区 | G18: 44402 | H18: 44402 | I18: 44411 | J18: 44412 | K18: 44412 | L18: 1 | M18: Sinovac | N18: 44392 | O18: =VLOOKUP(A18,Sheet2!C68:F202,4,FALSE) -> 36.8 | P18: =VLOOKUP(A18,Sheet2!C68:F202,4,FALSE) -> 36.8
A19: 79 | B19: Female | C19: 58 | D19: Moderate | E19: 张家界 | F19: 永定区 | G19: 44405 | H19: 44405 | I19: 44413 | J19: 44413 | K19: 44413 | L19: 1 | M19: Sinopharm | N19: 44390 | O19: =VLOOKUP(A19,Sheet2!C80:F214,4,FALSE) -> 22.21 | P19: =VLOOKUP(A19,Sheet2!C80:F214,4,FALSE) -> 22.21
A20: 77 | B20: Male | C20: 22 | D20: Moderate | E20: 张家界 | F20: 永定区 | G20: 44404 | H20: 44404 | I20: 44411 | J20: 44413 | K20: 44413 | L20: 1 | M20: Sinovac | N20: 44389 | O20: =VLOOKUP(A20,Sheet2!C78:F212,4,FALSE) -> 18.88 | P20: =VLOOKUP(A20,Sheet2!C78:F212,4,FALSE) -> 18.88
A21: 36 | B21: Female | C21: 43 | D21: Moderate | E21: 张家界 | F21: 永定区 | G21: 44401 | H21: 44401 | I21: 44403 | J21: 44409 | K21: 44409 | L21: 1 | M21: Sinopharm | N21: 44384
A22: 57 | B22: Male | C22: 49 | D22: Moderate | E22: 张家界 | F22: 永定区 | G22: 44397 | H22: 44397 | I22: 44411 | J22: 44411 | K22: 44411 | L22: 1 | M22: Sinovac | N22: 44385
A23: 51 | B23: Male | C23: 30 | D23: Moderate | E23: 张家界 | F23: 永定区 | G23: 44404 | H23: 44404 | I23: 44409 | J23: 44410 | K23: 44410 | L23: 1 | M23: Sinopharm | N23: 44384 | O23: =VLOOKUP(A23,Sheet2!C52:F186,4,FALSE) -> 30.88 | P23: =VLOOKUP(A23,Sheet2!C52:F186,4,FALSE) -> 30.88
A24: 116 | B24: Female | C24: 63 | D24: Moderate | E24: 张家界 | F24: 永定区 | I24: 44418 | J24: 44419 | K24: 44419 | L24: 1 | M24: Sinopharm | N24: 44390 | O24: =VLOOKUP(A24,Sheet2!C117:F251,4,FALSE) -> 33.16 | P24: =VLOOKUP(A24,Sheet2!C117:F251,4,FALSE) -> 33.16
A25: 82 | B25: Female | C25: 18 | D25: Moderate | E25: 张家界 | F25: 永定区 | G25: 44401 | H25: 44401 | I25: 44409 | J25: 44413 | K25: 44413 | L25: 1 | N25: 44384 | O25: =VLOOKUP(A25,Sheet2!C83:F217,4,FALSE) -> 27.48 | P25: =VLOOKUP(A25,Sheet2!C83:F217,4,FALSE) -> 27.48
A26: 25 | B26: Female | C26: 36 | D26: Moderate | E26: 长沙 | F26: 天心区 | G26: 44402 | H26: 44402 | I26: 44407 | J26: 44408 | K26: 44408 | L26: 1 | M26: Zhifei | N26: 44379
A27: 15 | B27: Female | C27: 34 | D27: Asymptomatic | E27: 长沙 | F27: 宁乡市 | G27: 44401 | H27: 44401 | I27: 44407 | J27: 44407 | K27: 44407 | L27: 1 | M27: Zhifei | N27: 44378
A28: 117 | B28: Male | C28: 31 | D28: Moderate | E28: 张家界 | F28: 永定区 | I28: 44419 | J28: 44419 | K28: 44419 | L28: 1 | M28: Sinovac | N28: 44384 | O28: =VLOOKUP(A28,Sheet2!C118:F252,4,FALSE) -> 38.12 | P28: =VLOOKUP(A28,Sheet2!C118:F252,4,FALSE) -> 38.12
A29: 87 | B29: Male | C29: 39 | D29: Moderate | E29: 张家界 | F29: 永定区 | G29: 44406 | H29: 44406 | I29: 44414 | J29: 44414 | K29: 44414 | L29: 1 | M29: Zhifei | N29: 44379 | O29: =VLOOKUP(A29,Sheet2!C88:F222,4,FALSE) -> 20.08 | P29: =VLOOKUP(A29,Sheet2!C88:F222,4,FALSE) -> 20.08
A30: 6 | B30: Female | C30: 39 | D30: Moderate | E30: 株洲 | F30: 石峰区 | G30: 44401 | H30: 44401 | I30: 44404 | J30: 44406 | K30: 44406 | L30: 2 | M30: Sinopharm | N30: 44371 | O30: =VLOOKUP(A30,Sheet2!C7:F141,4,FALSE) -> 37.1 | P30: =VLOOKUP(A30,Sheet2!C7:F141,4,FALSE) -> 37.1
A31: 121 | B31: Female | C31: 26 | D31: Moderate | E31: 张家界 | F31: 永定区 | I31: 44418 | J31: 44419 | K31: 44419 | L31: 1 | M31: Sinovac | N31: 44383 | O31: =VLOOKUP(A31,Sheet2!C122:F256,4,FALSE) -> 22.46 | P31: =VLOOKUP(A31,Sheet2!C122:F256,4,FALSE) -> 22.46
A32: 113 | B32: Male | C32: 48 | D32: Mild | E32: 张家界 | F32: 永定区 | I32: 44417 | J32: 44418 | K32: 44418 | L32: 1 | M32: Sinovac | N32: 44382 | O32: =VLOOKUP(A32,Sheet2!C114:F248,4,FALSE) -> 34 | P32: =VLOOKUP(A32,Sheet2!C114:F248,4,FALSE) -> 34
A33: 128 | C33: 54 | D33: Moderate | I33: 44422 | J33: 44422 | K33: 44422 | L33: 1 | M33: Sinopharm | N33: 44384 | O33: =VLOOKUP(A33,Sheet2!C129:F263,4,FALSE) -> 23.98 | P33: =VLOOKUP(A33,Sheet2!C129:F263,4,FALSE) -> 23.98
A34: 53 | B34: Male | C34: 68 | D34: Asymptomatic | E34: 益阳 | F34: 赫山区 | G34: 44401 | H34: 44401 | I34: 44410 | J34: 44411 | K34: 44411 | L34: 2 | M34: Sinovac | N34: 44373 | O34: =VLOOKUP(A34,Sheet2!C54:F188,4,FALSE) -> 19.97 | P34: =VLOOKUP(A34,Sheet2!C54:F188,4,FALSE) -> 19.97
A35: 8 | B35: Female | C35: 38 | D35: Moderate | E35: 张家界 | F35: 永定区 | G35: 44394 | H35: 44394 | I35: 44400 | J35: 44406 | K35: 44406 | L35: 2 | N35: 44368 | O35: =VLOOKUP(A35,Sheet2!C9:F143,4,FALSE) -> 37.66 | P35: =VLOOKUP(A35,Sheet2!C9:F143,4,FALSE) -> 37.66
A36: 55 | B36: Female | C36: 34 | D36: Moderate | E36: 张家界 | F36: 永定区 | G36: 44399 | H36: 44399 | I36: 44410 | J36: 44411 | K36: 44411 | L36: 2 | M36: Sinovac | N36: 44372 | O36: =VLOOKUP(A36,Sheet2!C56:F190,4,FALSE) -> 20.14 | P36: =VLOOKUP(A36,Sheet2!C56:F190,4,FALSE) -> 20.14
A37: 27 | B37: Female | C37: 33 | D37: Moderate | E37: 湘西 | F37: 古丈县 | G37: 44403 | H37: 44403 | I37: 44408 | J37: 44408 | K37: 44408 | L37: 2 | M37: Sinovac | N37: 44369
A38: 38 | B38: Male | C38: 31 | D38: Mild | E38: 张家界 | F38: 永定区 | G38: 44404 | H38: 44404 | I38: 44406 | J38: 44409 | K38: 44409 | L38: 2 | M38: Sinopharm | N38: 44368 | O38: =VLOOKUP(A38,Sheet2!C39:F173,4,FALSE) -> 24.21 | P38: =VLOOKUP(A38,Sheet2!C39:F173,4,FALSE) -> 24.21
A39: 1 | B39: Female | C39: 36 | D39: Asymptomatic | E39: 常德 | F39: 武陵区 | G39: 44400 | H39: 44400 | I39: 44404 | J39: 44405 | K39: 44405 | L39: 2 | M39: Sinopharm | N39: 44363
A40: 97 | B40: Male | C40: 36 | D40: Mild | E40: 张家界 | F40: 永定区 | I40: 44414 | J40: 44416 | K40: 44416 | L40: 1 | M40: Zhifei | N40: 44373
...

Sheet Sheet2
A1: 序号 | B1: 姓名 | C1: 序号 | D1: 感染来源 | E1: N | F1: O
A2: 1 | B2: 周晓晶 | C2: 1
A3: 2 | B3: 罗宇轩 | C3: 2
A4: 3 | B4: 杨小玲 | C4: 3 | D4: 曾娟
A5: 4 | B5: 刘阳 | C5: 4
A6: 5 | B6: 李锦昊 | C6: 5
A7: 6 | B7: 沈朝霞 | C7: 6 | E7: 35.5 | F7: 37.1
A8: 7 | B8: 杨文俊 | C8: 7 | E8: 37.55 | F8: 37.52
A9: 8 | B9: 曾娟 | C9: 8 | E9: 37.66 | F9: 37.66
A10: 9 | B10: 蔡雪霞 | C10: 9 | E10: 24.18 | F10: 23.61
A11: 10 | B11: 沈招安 | C11: 10
A12: 11 | B12: 龙思雨 | C12: 11 | E12: 37.8 | F12: 37.1
A13: 12 | B13: 曾媛 | C13: 12
A14: 13 | B14: 言睿麒 | C14: 13
A15: 14 | B15: 言苇麟 | C15: 14
A16: 15 | B16: 唐江 | C16: 15
A17: 16 | B17: 张燕玲 | C17: 16
A18: 17 | B18: 欧珍 | C18: 17 | D18: 杨小玲 | E18: 20.05 | F18: 21
A19: 18 | B19: 邓集晖 | C19: 18 | D19: 杨小玲 | E19: 23.55 | F19: 24.49
A20: 19 | B20: 江双凤 | C20: 19 | D20: 杨小玲 | E20: 36.06 | F20: 34.89
A21: 20 | B21: 黄丽君 | C21: 20 | D21: 沈朝霞 | E21: 35.9 | F21: 36
A22: 21 | B22: 言艾轩 | C22: 21 | D22: 言睿麒 | E22: 27.3 | F22: 27.7
A23: 22 | B23: 沈东宇 | C23: 22
A24: 23 | B24: 沈思齐 | C24: 23 | D24: 沈招安 | E24: 30.5 | F24: 30
A25: 24 | B25: 杨立军 | C25: 24 | D25: 沈朝霞 | E25: 31.3 | F25: 32.32
A26: 25 | B26: 方迎 | C26: 25 | D26: 刘某果
A27: 26 | B27: 石红春 | C27: 26 | D27: 江双凤 | E27: 22.9 | F27: 23.57
A28: 27 | B28: 孙莉 | C28: 27
A29: 28 | B29: 张蔷薇 | C29: 28 | D29: 石红春
A30: 29 | B30: 张珈睿 | C30: 29 | D30: 石红春
A31: 30 | B31: 肖云熙 | C31: 30
A32: 31 | B32: 谭博友 | C32: 31
A33: 32 | B33: 何乐高 | C33: 32 | E33: 26.06 | F33: 27.04
A34: 33 | B34: 刘巧可 | C34: 33 | E34: 27.96 | F34: 28.75
A35: 34 | B35: 刘若镜 | C35: 34 | E35: 31.4 | F35: 31.74
A36: 35 | B36: 刘建宜 | C36: 35 | E36: 27.32 | F36: 27.45
A37: 36 | B37: 胡满玉 | C37: 36
A38: 37 | B38: 胡银华 | C38: 37 | D38: 石红春
A39: 38 | B39: 王凯成 | C39: 38 | D39: 胡满玉 | E39: 23.62 | F39: 24.21
A40: 39 | B40: 田蕾 | C40: 39 | D40: 曾娟
...

Sheet Sheet3
