Workbook

Sheet main
A1: id | B1: age | C1: gender | D1: vaccine | E1: vaccine_type | F1: vaccine_mix | G1: outcome | H1: lastexposedate | I1: vaccinelastdate | J1: id_cases
A2: 6 | B2: 4 | C2: Female | D2: 1 | E2: P | F2: N | G2: 0 | H2: 44574 | I2: 44564 | J2: 1
A3: 11 | B3: 31 | C3: Male | D3: 3 | E3: PPP | F3: N | G3: 0 | H3: 44569 | I3: 44564 | J3: 1
A4: 29 | B4: 34 | C4: Female | D4: 2 | E4: PP | F4: N | G4: 0 | H4: 44569 | I4: 44574 | J4: 1
A5: 33 | B5: 22 | C5: Male | D5: 2 | E5: VV | F5: N | G5: 0 | H5: 44569 | I5: 44569 | J5: 1
A6: 64 | B6: 59 | C6: Male | D6: 1 | E6: P | F6: N | G6: 0 | H6: 44569 | I6: 44569 | J6: 1
A7: 66 | B7: 46 | C7: Male | D7: 3 | E7: PPP | F7: N | G7: 0 | H7: 44569 | I7: 44570 | J7: 1
A8: 100 | B8: 30 | C8: Male | D8: 3 | E8: PPP | F8: N | G8: 0 | H8: 44569 | I8: 44571 | J8: 1
A9: 109 | B9: 57 | C9: Female | D9: 3 | E9: PVV | F9: Y | G9: 1 | H9: 44574 | I9: 44563 | J9: 1
A10: 126 | B10: 50 | C10: Female | D10: 3 | E10: PPP | F10: N | G10: 0 | H10: 44569 | I10: 44572 | J10: 1
A11: 127 | B11: 6 | C11: Female | D11: 2 | E11: PP | F11: N | G11: 0 | H11: 44569 | I11: 44562 | J11: 1
A12: 135 | B12: 53 | C12: Female | D12: 3 | E12: PPP | F12: N | G12: 0 | H12: 44569 | I12: 44563 | J12: 1
A13: 136 | B13: 31 | C13: Female | D13: 3 | E13: PPP | F13: N | G13: 0 | H13: 44569 | I13: 44567 | J13: 1
... A130: 2288 | B130: 24 | C130: Male | D130: 3 | E130: PPP | F130: N | G130: 0 | H130: 44574 | I130: 44572 | J130: 22
A131: 2307 | D131: 3 | E131: PPP | F131: N | G131: 0 | H131: 44577 | I131: 44565 | J131: 23
A132: 2309 | D132: 3 | E132: PPP | F132: N | G132: 0 | H132: 44577 | I132: 44565 | J132: 23
A133: 2330 | D133: 3 | E133: PVV | F133: Y | G133: 0 | H133: 44577 | I133: 44573 | J133: 23
A134: 2340 | D134: 3 | E134: PPP | F134: N | G134: 0 | H134: 44577 | I134: 44574 | J134: 23
A135: 2346 | D135: 3 | E135: PPP | F135: N | G135: 0 | H135: 44577 | I135: 44567 | J135: 23
A136: 2359 | D136: 2 | E136: AA | F136: N | G136: 0 | H136: 44577 | I136: 44571 | J136: 23
A137: 2406 | B137: 38 | C137: Male | D137: 3 | E137: PPP | F137: N | G137: 0 | H137: 44576 | I137: 44573 | J137: 24
A138: 2419 | B138: 5 | C138: Female | D138: 2 | E138: PP | F138: N | G138: 0 | H138: 44576 | I138: 44564 | J138: 24
A139: 2421 | B139: 35 | C139: Female | D139: 3 | E139: PVV | F139: Y | G139: 0 | H139: 44576 | I139: 44571 | J139: 24
A140: 2430 | B140: 32 | C140: Female | D140: 3 | E140: PPP | F140: N | G140: 0 | H140: 44576 | I140: 44571 | J140: 24
A141: 2434 | B141: 35 | C141: Female | D141: 3 | E141: PPP | F141: N | G141: 0 | H141: 44576 | I141: 44564 | J141: 24
A142: 2458 | B142: 53 | C142: Female | D142: 3 | E142: PPP | F142: N | G142: 0 | H142: 44576 | I142: 44573 | J142: 25
A143: 2462 | B143: 25 | C143: Male | D143: 3 | E143: VVV | F143: N | G143: 0 | H143: 44578 | I143: 44572 | J143: 25
A144: 2463 | B144: 31 | C144: Female | D144: 3 | E144: PPP | F144: N | G144: 0 | H144: 44576 | I144: 44564 | J144: 25
A145: 2475 | B145: 48 | C145: Female | D145: 3 | E145: VVV | F145: N | G145: 0 | H145: 44577 | I145: 44565 | J145: 25
A146: 2494 | B146: 57 | C146: Female | D146: 3 | E146: PPP | F146: N | G146: 0 | H146: 44578 | I146: 44572 | J146: 25
A147: 2504 | B147: 32 | C147: Female | D147: 3 | E147: PPP | F147: N | G147: 0 | H147: 44578 | I147: 44570 | J147: 25
A148: 2523 | B148: 33 | C148: Male | D148: 3 | E148: PPP | F148: N | G148: 0 | H148: 44578 | I148: 44570 | J148: 25
... A195: 1175 | B195: 36 | C195: Male | D195: 3 | E195: PPP | F195: N | G195: 0 | H195: 44574 | I195: 44560 | J195: 14
A196: 2326 | D196: 3 | E196: PPP | F196: N | G196: 0 | H196: 44577 | I196: 44560 | J196: 23
A197: 2367 | D197: 3 | E197: PPP | F197: N | G197: 0 | H197: 44577 | I197: 44560 | J197: 23
A198: 112 | B198: 48 | C198: Male | D198: 3 | E198: PPP | F198: N | G198: 0 | H198: 44574 | I198: 44560 | J198: 1
A199: 453 | B199: 50 | C199: Male | D199: 3 | E199: PPP | F199: N | G199: 0 | H199: 44569 | I199: 44560 | J199: 1
A200: 521 | B200: 40 | C200: Female | D200: 3 | E200: PPP | F200: N | G200: 0 | H200: 44569 | I200: 44560 | J200: 1
A201: 623 | B201: 34 | C201: Female | D201: 3 | E201: PPP | F201: N | G201: 0 | H201: 44576 | I201: 44560 | J201: 10
A202: 661 | B202: 48 | C202: Male | D202: 3 | E202: PVV | F202: Y | G202: 0 | H202: 44576 | I202: 44560 | J202: 10
...

Sheet Sheet2
A1: id | B1: id_name | C1: id_cases | D1: name | E1: gender | F1: gender | G1: age | H1: lastexposedate | J1: lastvaccinedate | K1: outcome | L1: vaccine | M1: aaa | N1: vaccine_type | O1: vaccine_mix | P1: 第一针接种日期 | Q1: 第一针厂家 | R1: 第二针接种日期 | S1: 第二针厂家 | T1: 第三针接种日期 | U1: 第三针厂家
A2: 6 | B2: 杨宏 | C2: =IFERROR(VLOOKUP(B2,code!$F$1:$G$39,2,FALSE),"") -> 1 | D2: 刘亦雯 | E2: =IF(F2="男","Male",IF(F2="女", "Female", "")) -> Female | F2: 女 | G2: 4 | H2: 44574 | I2: =IFERROR(DATEVALUE(H2),H2) -> 44574 | J2: =MAX(P2,R2,T2) -> 44564 | K2: =_xlfn.IFNA(VLOOKUP(D2,code!F:G,1,FALSE),"") | L2: 1 | M2: =Q2&"_"&S2&"_"&U2 -> 兰州生物__ | N2: =VLOOKUP(M2,code!A:B,2,FALSE) -> P | O2: =VLOOKUP(M2,code!A:C,3,FALSE) -> N | P2: 44564 | Q2: 兰州生物
A3: 11 | B3: 杨宏 | C3: =IFERROR(VLOOKUP(B3,code!$F$1:$G$39,2,FALSE),"") -> 1 | D3: 朱红星 | E3: =IF(F3="男","Male",IF(F3="女", "Female", "")) -> Male | F3: 男 | G3: 31 | H3: 2022-1-8 | I3: =IFERROR(DATEVALUE(H3),H3) -> 44569 | J3: =MAX(P3,R3,T3) -> 44564 | K3: =_xlfn.IFNA(VLOOKUP(D3,code!F:G,1,FALSE),"") | L3: 3 | M3: =Q3&"_"&S3&"_"&U3 -> 北京生物_兰州生物_兰州生物 | N3: =VLOOKUP(M3,code!A:B,2,FALSE) -> PPP | O3: =VLOOKUP(M3,code!A:C,3,FALSE) -> N | P3: 44352 | Q3: 北京生物 | R3: 44374 | S3: 兰州生物 | T3: 44564 | U3: 兰州生物
A4: 29 | B4: 杨宏 | C4: =IFERROR(VLOOKUP(B4,code!$F$1:$G$39,2,FALSE),"") -> 1 | D4: 黄巧玲 | E4: =IF(F4="男","Male",IF(F4="女", "Female", "")) -> Female | F4: 女 | G4: 34 | H4: 2022-1-8 | I4: =IFERROR(DATEVALUE(H4),H4) -> 44569 | J4: =MAX(P4,R4,T4) -> 44574 | K4: =_xlfn.IFNA(VLOOKUP(D4,code!F:G,1,FALSE),"") | L4: 2 | M4: =Q4&"_"&S4&"_"&U4 -> 北京生物_兰州生物_ | N4: =VLOOKUP(M4,code!A:B,2,FALSE) -> PP | O4: =VLOOKUP(M4,code!A:C,3,FALSE) -> N | P4: 44355 | Q4: 北京生物 | R4: 44574 | S4: 兰州生物
A5: 33 | B5: 杨宏 | C5: =IFERROR(VLOOKUP(B5,code!$F$1:$G$39,2,FALSE),"") -> 1 | D5: 宋小贤 | E5: =IF(F5="男","Male",IF(F5="女", "Female", "")) -> Male | F5: 男 | G5: 22 | H5: 2022-1-8 | I5: =IFERROR(DATEVALUE(H5),H5) -> 44569 | J5: =MAX(P5,R5,T5) -> 44569 | K5: =_xlfn.IFNA(VLOOKUP(D5,code!F:G,1,FALSE),"") | L5: 2 | M5: =Q5&"_"&S5&"_"&U5 -> 北京科兴中维_北京科兴中维_ | N5: =VLOOKUP(M5,code!A:B,2,FALSE) -> VV | O5: =VLOOKUP(M5,code!A:C,3,FALSE) -> N | P5: 44399 | Q5: 北京科兴中维 | R5: 44569 | S5: 北京科兴中维
A6: 64 | B6: 杨宏 | C6: =IFERROR(VLOOKUP(B6,code!$F$1:$G$39,2,FALSE),"") -> 1 | D6: 周容葵 | E6: =IF(F6="男","Male",IF(F6="女", "Female", "")) -> Male | F6: 男 | G6: 59 | H6: 2022-1-8 | I6: =IFERROR(DATEVALUE(H6),H6) -> 44569 | J6: =MAX(P6,R6,T6) -> 44569 | K6: =_xlfn.IFNA(VLOOKUP(D6,code!F:G,1,FALSE),"") | L6: 1 | M6: =Q6&"_"&S6&"_"&U6 -> 兰州生物__ | N6: =VLOOKUP(M6,code!A:B,2,FALSE) -> P | O6: =VLOOKUP(M6,code!A:C,3,FALSE) -> N | P6: 44569 | Q6: 兰州生物
A7: 66 | B7: 杨宏 | C7: =IFERROR(VLOOKUP(B7,code!$F$1:$G$39,2,FALSE),"") -> 1 | D7: 程双奎 | E7: =IF(F7="男","Male",IF(F7="女", "Female", "")) -> Male | F7: 男 | G7: 46 | H7: 2022-1-8 | I7: =IFERROR(DATEVALUE(H7),H7) -> 44569 | J7: =MAX(P7,R7,T7) -> 44570 | K7: =_xlfn.IFNA(VLOOKUP(D7,code!F:G,1,FALSE),"") | L7: 3 | M7: =Q7&"_"&S7&"_"&U7 -> 北京生物_兰州生物_长春生物 | N7: =VLOOKUP(M7,code!A:B,2,FALSE) -> PPP | O7: =VLOOKUP(M7,code!A:C,3,FALSE) -> N | P7: 44355 | Q7: 北京生物 | R7: 44376 | S7: 兰州生物 | T7: 44570 | U7: 长春生物
A8: 100 | B8: 杨宏 | C8: =IFERROR(VLOOKUP(B8,code!$F$1:$G$39,2,FALSE),"") -> 1 | D8: 林建安 | E8: =IF(F8="男","Male",IF(F8="女", "Female", "")) -> Male | F8: 男 | G8: 30 | H8: 2022-1-8 | I8: =IFERROR(DATEVALUE(H8),H8) -> 44569 | J8: =MAX(P8,R8,T8) -> 44571 | K8: =_xlfn.IFNA(VLOOKUP(D8,code!F:G,1,FALSE),"") | L8: 3 | M8: =Q8&"_"&S8&"_"&U8 -> 北京生物_北京生物_兰州生物 | N8: =VLOOKUP(M8,code!A:B,2,FALSE) -> PPP | O8: =VLOOKUP(M8,code!A:C,3,FALSE) -> N | P8: 44310 | Q8: 北京生物 | R8: 44383 | S8: 北京生物 | T8: 44571 | U8: 兰州生物
A9: 109 | B9: 杨宏 | C9: =IFERROR(VLOOKUP(B9,code!$F$1:$G$39,2,FALSE),"") -> 1 | D9: 杨简善 | E9: =IF(F9="男","Male",IF(F9="女", "Female", "")) -> Female | F9: 女 | G9: 57 | H9: 44574 | I9: =IFERROR(DATEVALUE(H9),H9) -> 44574 | J9: =MAX(P9,R9,T9) -> 44563 | K9: 1 | L9: 3 | M9: =Q9&"_"&S9&"_"&U9 -> 北京生物_北京科兴中维_北京科兴中维 | N9: =VLOOKUP(M9,code!A:B,2,FALSE) -> PVV | O9: =VLOOKUP(M9,code!A:C,3,FALSE) -> Y | P9: 44353 | Q9: 北京生物 | R9: 44379 | S9: 北京科兴中维 | T9: 44563 | U9: 北京科兴中维
A10: 126 | B10: 杨宏 | C10: =IFERROR(VLOOKUP(B10,code!$F$1:$G$39,2,FALSE),"") -> 1 | D10: 朱小琴 | E10: =IF(F10="男","Male",IF(F10="女", "Female", "")) -> Female | F10: 女 | G10: 50 | H10: 2022-1-8 | I10: =IFERROR(DATEVALUE(H10),H10) -> 44569 | J10: =MAX(P10,R10,T10) -> 44572 | K10: =_xlfn.IFNA(VLOOKUP(D10,code!F:G,1,FALSE),"") | L10: 3 | M10: =Q10&"_"&S10&"_"&U10 -> 北京生物_北京生物_兰州生物 | N10: =VLOOKUP(M10,code!A:B,2,FALSE) -> PPP | O10: =VLOOKUP(M10,code!A:C,3,FALSE) -> N | P10: 44353 | Q10: 北京生物 | R10: 44382 | S10: 北京生物 | T10: 44572 | U10: 兰州生物
A11: 127 | B11: 杨宏 | C11: =IFERROR(VLOOKUP(B11,code!$F$1:$G$39,2,FALSE),"") -> 1 | D11: 苏雨桐 | E11: =IF(F11="男","Male",IF(F11="女", "Female", "")) -> Female | F11: 女 | G11: 6 | H11: 2022-1-8 | I11: =IFERROR(DATEVALUE(H11),H11) -> 44569 | J11: =MAX(P11,R11,T11) -> 44562 | K11: =_xlfn.IFNA(VLOOKUP(D11,code!F:G,1,FALSE),"") | L11: 2 | M11: =Q11&"_"&S11&"_"&U11 -> 成都生物_兰州生物_ | N11: =VLOOKUP(M11,code!A:B,2,FALSE) -> PP | O11: =VLOOKUP(M11,code!A:C,3,FALSE) -> N | P11: 44509 | Q11: 成都生物 | R11: 44562 | S11: 兰州生物
A12: 135 | B12: 杨宏 | C12: =IFERROR(VLOOKUP(B12,code!$F$1:$G$39,2,FALSE),"") -> 1 | D12: 包善杰 | E12: =IF(F12="男","Male",IF(F12="女", "Female", "")) -> Female | F12: 女 | G12: 53 | H12: 2022-1-8 | I12: =IFERROR(DATEVALUE(H12),H12) -> 44569 | J12: =MAX(P12,R12,T12) -> 44563 | K12: =_xlfn.IFNA(VLOOKUP(D12,code!F:G,1,FALSE),"") | L12: 3 | M12: =Q12&"_"&S12&"_"&U12 -> 北京生物_北京生物_兰州生物 | N12: =VLOOKUP(M12,code!A:B,2,FALSE) -> PPP | O12: =VLOOKUP(M12,code!A:C,3,FALSE) -> N | P12: 44297 | Q12: 北京生物 | R12: 44346 | S12: 北京生物 | T12: 44563 | U12: 兰州生物
A13: 136 | B13: 杨宏 | C13: =IFERROR(VLOOKUP(B13,code!$F$1:$G$39,2,FALSE),"") -> 1 | D13: 黄舒琼 | E13: =IF(F13="男","Male",IF(F13="女", "Female", "")) -> Female | F13: 女 | G13: 31 | H13: 2022-1-8 | I13: =IFERROR(DATEVALUE(H13),H13) -> 44569 | J13: =MAX(P13,R13,T13) -> 44567 | K13: =_xlfn.IFNA(VLOOKUP(D13,code!F:G,1,FALSE),"") | L13: 3 | M13: =Q13&"_"&S13&"_"&U13 -> 北京生物_兰州生物_兰州生物 | N13: =VLOOKUP(M13,code!A:B,2,FALSE) -> PPP | O13: =VLOOKUP(M13,code!A:C,3,FALSE) -> N | P13: 44352 | Q13: 北京生物 | R13: 44375 | S13: 兰州生物 | T13: 44567 | U13: 兰州生物
A14: 144 | B14: 杨宏 | C14: =IFERROR(VLOOKUP(B14,code!$F$1:$G$39,2,FALSE),"") -> 1 | D14: 杨菲 | E14: =IF(F14="男","Male",IF(F14="女", "Female", "")) -> Female | F14: 女 | G14: 24 | H14: 2022-1-8 | I14: =IFERROR(DATEVALUE(H14),H14) -> 44569 | J14: =MAX(P14,R14,T14) -> 44570 | K14: =_xlfn.IFNA(VLOOKUP(D14,code!F:G,1,FALSE),"") | L14: 3 | M14: =Q14&"_"&S14&"_"&U14 -> 北京生物_兰州生物_兰州生物 | N14: =VLOOKUP(M14,code!A:B,2,FALSE) -> PPP | O14: =VLOOKUP(M14,code!A:C,3,FALSE) -> N | P14: 44353 | Q14: 北京生物 | R14: 44375 | S14: 兰州生物 | T14: 44570 | U14: 兰州生物
A15: 160 | B15: 杨宏 | C15: =IFERROR(VLOOKUP(B15,code!$F$1:$G$39,2,FALSE),"") -> 1 | D15: 何军华 | E15: =IF(F15="男","Male",IF(F15="女", "Female", "")) -> Male | F15: 男 | G15: 53 | H15: 2022-1-8 | I15: =IFERROR(DATEVALUE(H15),H15) -> 44569 | J15: =MAX(P15,R15,T15) -> 44569 | K15: =_xlfn.IFNA(VLOOKUP(D15,code!F:G,1,FALSE),"") | L15: 3 | M15: =Q15&"_"&S15&"_"&U15 -> 北京科兴中维_北京科兴中维_北京科兴中维 | N15: =VLOOKUP(M15,code!A:B,2,FALSE) -> VVV | O15: =VLOOKUP(M15,code!A:C,3,FALSE) -> N | P15: 44357 | Q15: 北京科兴中维 | R15: 44385 | S15: 北京科兴中维 | T15: 44569 | U15: 北京科兴中维
A16: 196 | B16: 杨宏 | C16: =IFERROR(VLOOKUP(B16,code!$F$1:$G$39,2,FALSE),"") -> 1 | D16: 张彤惜 | E16: =IF(F16="男","Male",IF(F16="女", "Female", "")) -> Female | F16: 女 | G16: 4 | H16: 44574 | I16: =IFERROR(DATEVALUE(H16),H16) -> 44574 | J16: =MAX(P16,R16,T16) -> 44572 | K16: =_xlfn.IFNA(VLOOKUP(D16,code!F:G,1,FALSE),"") | L16: 2 | M16: =Q16&"_"&S16&"_"&U16 -> 成都生物_兰州生物_ | N16: =VLOOKUP(M16,code!A:B,2,FALSE) -> PP | O16: =VLOOKUP(M16,code!A:C,3,FALSE) -> N | P16: 44527 | Q16: 成都生物 | R16: 44572 | S16: 兰州生物
A17: 203 | B17: 杨宏 | C17: =IFERROR(VLOOKUP(B17,code!$F$1:$G$39,2,FALSE),"") -> 1 | D17: 高颂贻 | E17: =IF(F17="男","Male",IF(F17="女", "Female", "")) -> Female | F17: 女 | G17: 5 | H17: 44572 | I17: =IFERROR(DATEVALUE(H17),H17) -> 44572 | J17: =MAX(P17,R17,T17) -> 44570 | K17: =_xlfn.IFNA(VLOOKUP(D17,code!F:G,1,FALSE),"") | L17: 2 | M17: =Q17&"_"&S17&"_"&U17 -> 成都生物_兰州生物_ | N17: =VLOOKUP(M17,code!A:B,2,FALSE) -> PP | O17: =VLOOKUP(M17,code!A:C,3,FALSE) -> N | P17: 44520 | Q17: 成都生物 | R17: 44570 | S17: 兰州生物
A18: 222 | B18: 杨宏 | C18: =IFERROR(VLOOKUP(B18,code!$F$1:$G$39,2,FALSE),"") -> 1 | D18: 刘建林 | E18: =IF(F18="男","Male",IF(F18="女", "Female", "")) -> Male | F18: 男 | G18: 6 | H18: 44574 | I18: =IFERROR(DATEVALUE(H18),H18) -> 44574 | J18: =MAX(P18,R18,T18) -> 44570 | K18: =_xlfn.IFNA(VLOOKUP(D18,code!F:G,1,FALSE),"") | L18: 2 | M18: =Q18&"_"&S18&"_"&U18 -> 兰州生物_兰州生物_ | N18: =VLOOKUP(M18,code!A:B,2,FALSE) -> PP | O18: =VLOOKUP(M18,code!A:C,3,FALSE) -> N | P18: 44539 | Q18: 兰州生物 | R18: 44570 | S18: 兰州生物
A19: 250 | B19: 杨宏 | C19: =IFERROR(VLOOKUP(B19,code!$F$1:$G$39,2,FALSE),"") -> 1 | D19: 谭禹宸 | E19: =IF(F19="男","Male",IF(F19="女", "Female", "")) -> Male | F19: 男 | G19: 5 | H19: 44574 | I19: =IFERROR(DATEVALUE(H19),H19) -> 44574 | J19: =MAX(P19,R19,T19) -> 44569 | K19: =_xlfn.IFNA(VLOOKUP(D19,code!F:G,1,FALSE),"") | L19: 2 | M19: =Q19&"_"&S19&"_"&U19 -> 成都生物_兰州生物_ | N19: =VLOOKUP(M19,code!A:B,2,FALSE) -> PP | O19: =VLOOKUP(M19,code!A:C,3,FALSE) -> N | P19: 44518 | Q19: 成都生物 | R19: 44569 | S19: 兰州生物
A20: 253 | B20: 杨宏 | C20: =IFERROR(VLOOKUP(B20,code!$F$1:$G$39,2,FALSE),"") -> 1 | D20: 杨钰婷 | E20: =IF(F20="男","Male",IF(F20="女", "Female", "")) -> Female | F20: 女 | G20: 6 | H20: 44574 | I20: =IFERROR(DATEVALUE(H20),H20) -> 44574 | J20: =MAX(P20,R20,T20) -> 44566 | K20: =_xlfn.IFNA(VLOOKUP(D20,code!F:G,1,FALSE),"") | L20: 2 | M20: =Q20&"_"&S20&"_"&U20 -> 成都生物_兰州生物_ | N20: =VLOOKUP(M20,code!A:B,2,FALSE) -> PP | O20: =VLOOKUP(M20,code!A:C,3,FALSE) -> N | P20: 44539 | Q20: 成都生物 | R20: 44566 | S20: 兰州生物
A21: 257 | B21: 杨宏 | C21: =IFERROR(VLOOKUP(B21,code!$F$1:$G$39,2,FALSE),"") -> 1 | D21: 麦嘉诚 | E21: =IF(F21="男","Male",IF(F21="女", "Female", "")) -> Male | F21: 男 | G21: 5 | H21: 44574 | I21: =IFERROR(DATEVALUE(H21),H21) -> 44574 | J21: =MAX(P21,R21,T21) -> 44569 | K21: =_xlfn.IFNA(VLOOKUP(D21,code!F:G,1,FALSE),"") | L21: 2 | M21: =Q21&"_"&S21&"_"&U21 -> 成都生物_兰州生物_ | N21: =VLOOKUP(M21,code!A:B,2,FALSE) -> PP | O21: =VLOOKUP(M21,code!A:C,3,FALSE) -> N | P21: 44521 | Q21: 成都生物 | R21: 44569 | S21: 兰州生物
A22: 275 | B22: 杨宏 | C22: =IFERROR(VLOOKUP(B22,code!$F$1:$G$39,2,FALSE),"") -> 1 | D22: 郑苏雅 | E22: =IF(F22="男","Male",IF(F22="女", "Female", "")) -> Female | F22: 女 | G22: 4 | H22: 44574 | I22: =IFERROR(DATEVALUE(H22),H22) -> 44574 | J22: =MAX(P22,R22,T22) -> 44571 | K22: =_xlfn.IFNA(VLOOKUP(D22,code!F:G,1,FALSE),"") | L22: 1 | M22: =Q22&"_"&S22&"_"&U22 -> 兰州生物__ | N22: =VLOOKUP(M22,code!A:B,2,FALSE) -> P | O22: =VLOOKUP(M22,code!A:C,3,FALSE) -> N | P22: 44571 | Q22: 兰州生物
A23: 293 | B23: 杨宏 | C23: =IFERROR(VLOOKUP(B23,code!$F$1:$G$39,2,FALSE),"") -> 1 | D23: 李欣芸 | E23: =IF(F23="男","Male",IF(F23="女", "Female", "")) -> Female | F23: 女 | G23: 4 | H23: 44574 | I23: =IFERROR(DATEVALUE(H23),H23) -> 44574 | J23: =MAX(P23,R23,T23) -> 44571 | K23: =_xlfn.IFNA(VLOOKUP(D23,code!F:G,1,FALSE),"") | L23: 1 | M23: =Q23&"_"&S23&"_"&U23 -> 兰州生物__ | N23: =VLOOKUP(M23,code!A:B,2,FALSE) -> P | O23: =VLOOKUP(M23,code!A:C,3,FALSE) -> N | P23: 44571 | Q23: 兰州生物
A24: 995 | B24: 莫谏妹 | C24: =IFERROR(VLOOKUP(B24,code!$F$1:$G$39,2,FALSE),"") -> 12 | D24: 吴怀忠 | E24: =IF(F24="男","Male",IF(F24="女", "Female", "")) -> Male | F24: 男 | G24: 38 | H24: 44574 | I24: =IFERROR(DATEVALUE(H24),H24) -> 44574 | J24: =MAX(P24,R24,T24) -> 44541 | K24: =_xlfn.IFNA(VLOOKUP(D24,code!F:G,1,FALSE),"") | L24: 3 | M24: =Q24&"_"&S24&"_"&U24 -> 北京科兴中维__北京科兴中维 | N24: =VLOOKUP(M24,code!A:B,2,FALSE) -> V_V | O24: =VLOOKUP(M24,code!A:C,3,FALSE) -> N | P24: 44293 | Q24: 北京科兴中维 | T24: 44541 | U24: 北京科兴中维
A25: 294 | B25: 杨宏 | C25: =IFERROR(VLOOKUP(B25,code!$F$1:$G$39,2,FALSE),"") -> 1 | D25: 曾雨汐 | E25: =IF(F25="男","Male",IF(F25="女", "Female", "")) -> Female | F25: 女 | G25: 4 | H25: 44574 | I25: =IFERROR(DATEVALUE(H25),H25) -> 44574 | J25: =MAX(P25,R25,T25) -> 44570 | K25: =_xlfn.IFNA(VLOOKUP(D25,code!F:G,1,FALSE),"") | L25: 2 | M25: =Q25&"_"&S25&"_"&U25 -> 成都生物_兰州生物_ | N25: =VLOOKUP(M25,code!A:B,2,FALSE) -> PP | O25: =VLOOKUP(M25,code!A:C,3,FALSE) -> N | P25: 44521 | Q25: 成都生物 | R25: 44570 | S25: 兰州生物
A26: 299 | B26: 杨宏 | C26: =IFERROR(VLOOKUP(B26,code!$F$1:$G$39,2,FALSE),"") -> 1 | D26: 莫青梅 | E26: =IF(F26="男","Male",IF(F26="女", "Female", "")) -> Female | F26: 女 | G26: 28 | H26: 44574 | I26: =IFERROR(DATEVALUE(H26),H26) -> 44574 | J26: =MAX(P26,R26,T26) -> 44565 | K26: 1 | L26: 3 | M26: =Q26&"_"&S26&"_"&U26 -> 北京生物_兰州生物_兰州生物 | N26: =VLOOKUP(M26,code!A:B,2,FALSE) -> PPP | O26: =VLOOKUP(M26,code!A:C,3,FALSE) -> N | P26: 44353 | Q26: 北京生物 | R26: 44374 | S26: 兰州生物 | T26: 44565 | U26: 兰州生物
A27: 304 | B27: 杨宏 | C27: =IFERROR(VLOOKUP(B27,code!$F$1:$G$39,2,FALSE),"") -> 1 | D27: 谢米诺 | E27: =IF(F27="男","Male",IF(F27="女", "Female", "")) -> Male | F27: 男 | G27: 4 | H27: 44574 | I27: =IFERROR(DATEVALUE(H27),H27) -> 44574 | J27: =MAX(P27,R27,T27) -> 44569 | K27: 1 | L27: 2 | M27: =Q27&"_"&S27&"_"&U27 -> 兰州生物_兰州生物_ | N27: =VLOOKUP(M27,code!A:B,2,FALSE) -> PP | O27: =VLOOKUP(M27,code!A:C,3,FALSE) -> N | P27: 44534 | Q27: 兰州生物 | R27: 44569 | S27: 兰州生物
A28: 345 | B28: 杨宏 | C28: =IFERROR(VLOOKUP(B28,code!$F$1:$G$39,2,FALSE),"") -> 1 | D28: 周小灵 | E28: =IF(F28="男","Male",IF(F28="女", "Female", "")) -> Female | F28: 女 | G28: 54 | H28: 44574 | I28: =IFERROR(DATEVALUE(H28),H28) -> 44574 | J28: =MAX(P28,R28,T28) -> 44567 | K28: =_xlfn.IFNA(VLOOKUP(D28,code!F:G,1,FALSE),"") | L28: 3 | M28: =Q28&"_"&S28&"_"&U28 -> 北京科兴中维_北京生物_兰州生物 | N28: =VLOOKUP(M28,code!A:B,2,FALSE) -> VPP | O28: =VLOOKUP(M28,code!A:C,3,FALSE) -> Y | P28: 44294 | Q28: 北京科兴中维 | R28: 44339 | S28: 北京生物 | T28: 44567 | U28: 兰州生物
A29: 370 | B29: 杨宏 | C29: =IFERROR(VLOOKUP(B29,code!$F$1:$G$39,2,FALSE),"") -> 1 | D29: 温靖杰 | E29: =IF(F29="男","Male",IF(F29="女", "Female", "")) -> Male | F29: 男 | G29: 5 | H29: 2022-1-13 | I29: =IFERROR(DATEVALUE(H29),H29) -> 44574 | J29: =MAX(P29,R29,T29) -> 44564 | K29: =_xlfn.IFNA(VLOOKUP(D29,code!F:G,1,FALSE),"") | L29: 2 | M29: =Q29&"_"&S29&"_"&U29 -> 成都生物_兰州生物_ | N29: =VLOOKUP(M29,code!A:B,2,FALSE) -> PP | O29: =VLOOKUP(M29,code!A:C,3,FALSE) -> N | P29: 44513 | Q29: 成都生物 | R29: 44564 | S29: 兰州生物
A30: 419 | B30: 杨宏 | C30: =IFERROR(VLOOKUP(B30,code!$F$1:$G$39,2,FALSE),"") -> 1 | D30: 江文盛 | E30: =IF(F30="男","Male",IF(F30="女", "Female", "")) -> Male | F30: 男 | G30: 4 | H30: 2022-1-13 | I30: =IFERROR(DATEVALUE(H30),H30) -> 44574 | J30: =MAX(P30,R30,T30) -> 44569 | K30: =_xlfn.IFNA(VLOOKUP(D30,code!F:G,1,FALSE),"") | L30: 2 | M30: =Q30&"_"&S30&"_"&U30 -> 成都生物_兰州生物_ | N30: =VLOOKUP(M30,code!A:B,2,FALSE) -> PP | O30: =VLOOKUP(M30,code!A:C,3,FALSE) -> N | P30: 44528 | Q30: 成都生物 | R30: 44569 | S30: 兰州生物
A31: 428 | B31: 杨宏 | C31: =IFERROR(VLOOKUP(B31,code!$F$1:$G$39,2,FALSE),"") -> 1 | D31: 杨均宇 | E31: =IF(F31="男","Male",IF(F31="女", "Female", "")) -> Male | F31: 男 | G31: 4 | H31: 2022-1-13 | I31: =IFERROR(DATEVALUE(H31),H31) -> 44574 | J31: =MAX(P31,R31,T31) -> 44565 | K31: =_xlfn.IFNA(VLOOKUP(D31,code!F:G,1,FALSE),"") | L31: 1 | M31: =Q31&"_"&S31&"_"&U31 -> 兰州生物__ | N31: =VLOOKUP(M31,code!A:B,2,FALSE) -> P | O31: =VLOOKUP(M31,code!A:C,3,FALSE) -> N | P31: 44565 | Q31: 兰州生物
A32: 438 | B32: 杨宏 | C32: =IFERROR(VLOOKUP(B32,code!$F$1:$G$39,2,FALSE),"") -> 1 | D32: 吴祖柱 | E32: =IF(F32="男","Male",IF(F32="女", "Female", "")) -> Male | F32: 男 | G32: 35 | H32: 2022-1-8 | I32: =IFERROR(DATEVALUE(H32),H32) -> 44569 | J32: =MAX(P32,R32,T32) -> 44570 | K32: =_xlfn.IFNA(VLOOKUP(D32,code!F:G,1,FALSE),"") | L32: 3 | M32: =Q32&"_"&S32&"_"&U32 -> 北京生物_北京生物_兰州生物 | N32: =VLOOKUP(M32,code!A:B,2,FALSE) -> PPP | O32: =VLOOKUP(M32,code!A:C,3,FALSE) -> N | P32: 44297 | Q32: 北京生物 | R32: 44347 | S32: 北京生物 | T32: 44570 | U32: 兰州生物
A33: 457 | B33: 杨宏 | C33: =IFERROR(VLOOKUP(B33,code!$F$1:$G$39,2,FALSE),"") -> 1 | D33: 黄兆平 | E33: =IF(F33="男","Male",IF(F33="女", "Female", "")) -> Male | F33: 男 | G33: 27 | H33: 2022-1-8 | I33: =IFERROR(DATEVALUE(H33),H33) -> 44569 | J33: =MAX(P33,R33,T33) -> 44572 | K33: =_xlfn.IFNA(VLOOKUP(D33,code!F:G,1,FALSE),"") | L33: 3 | M33: =Q33&"_"&S33&"_"&U33 -> 北京科兴中维_北京科兴中维_北京科兴中维 | N33: =VLOOKUP(M33,code!A:B,2,FALSE) -> VVV | O33: =VLOOKUP(M33,code!A:C,3,FALSE) -> N | P33: 44346 | Q33: 北京科兴中维 | R33: 44368 | S33: 北京科兴中维 | T33: 44572 | U33: 北京科兴中维
A34: 476 | B34: 杨宏 | C34: =IFERROR(VLOOKUP(B34,code!$F$1:$G$39,2,FALSE),"") -> 1 | D34: 雷沁 | E34: =IF(F34="男","Male",IF(F34="女", "Female", "")) -> Female | F34: 女 | G34: 28 | H34: 2022-1-8 | I34: =IFERROR(DATEVALUE(H34),H34) -> 44569 | J34: =MAX(P34,R34,T34) -> 44562 | K34: =_xlfn.IFNA(VLOOKUP(D34,code!F:G,1,FALSE),"") | L34: 3 | M34: =Q34&"_"&S34&"_"&U34 -> 北京科兴中维_北京科兴中维_北京科兴中维 | N34: =VLOOKUP(M34,code!A:B,2,FALSE) -> VVV | O34: =VLOOKUP(M34,code!A:C,3,FALSE) -> N | P34: 44300 | Q34: 北京科兴中维 | R34: 44328 | S34: 北京科兴中维 | T34: 44562 | U34: 北京科兴中维
A35: 484 | B35: 杨宏 | C35: =IFERROR(VLOOKUP(B35,code!$F$1:$G$39,2,FALSE),"") -> 1 | D35: 余子阳 | E35: =IF(F35="男","Male",IF(F35="女", "Female", "")) -> Male | F35: 男 | G35: 6 | H35: 2022-1-13 | I35: =IFERROR(DATEVALUE(H35),H35) -> 44574 | J35: =MAX(P35,R35,T35) -> 44569 | K35: =_xlfn.IFNA(VLOOKUP(D35,code!F:G,1,FALSE),"") | L35: 1 | M35: =Q35&"_"&S35&"_"&U35 -> 兰州生物__ | N35: =VLOOKUP(M35,code!A:B,2,FALSE) -> P | O35: =VLOOKUP(M35,code!A:C,3,FALSE) -> N | P35: 44569 | Q35: 兰州生物
A36: 488 | B36: 杨宏 | C36: =IFERROR(VLOOKUP(B36,code!$F$1:$G$39,2,FALSE),"") -> 1 | D36: 胡鹏程 | E36: =IF(F36="男","Male",IF(F36="女", "Female", "")) -> Male | F36: 男 | G36: 34 | H36: 2022-1-8 | I36: =IFERROR(DATEVALUE(H36),H36) -> 44569 | J36: =MAX(P36,R36,T36) -> 44569 | K36: =_xlfn.IFNA(VLOOKUP(D36,code!F:G,1,FALSE),"") | L36: 3 | M36: =Q36&"_"&S36&"_"&U36 -> 成都生物_北京生物_兰州生物 | N36: =VLOOKUP(M36,code!A:B,2,FALSE) -> PPP | O36: =VLOOKUP(M36,code!A:C,3,FALSE) -> N | P36: 44317 | Q36: 成都生物 | R36: 44352 | S36: 北京生物 | T36: 44569 | U36: 兰州生物
A37: 495 | B37: 杨宏 | C37: =IFERROR(VLOOKUP(B37,code!$F$1:$G$39,2,FALSE),"") -> 1 | D37: 徐家宝 | E37: =IF(F37="男","Male",IF(F37="女", "Female", "")) -> Male | F37: 男 | G37: 22 | H37: 2022-1-8 | I37: =IFERROR(DATEVALUE(H37),H37) -> 44569 | J37: =MAX(P37,R37,T37) -> 44567 | K37: =_xlfn.IFNA(VLOOKUP(D37,code!F:G,1,FALSE),"") | L37: 3 | M37: =Q37&"_"&S37&"_"&U37 -> 成都生物__北京科兴中维 | N37: =VLOOKUP(M37,code!A:B,2,FALSE) -> P_V | O37: =VLOOKUP(M37,code!A:C,3,FALSE) -> Y | P37: 44316 | Q37: 成都生物 | T37: 44567 | U37: 北京科兴中维
A38: 500 | B38: 杨宏 | C38: =IFERROR(VLOOKUP(B38,code!$F$1:$G$39,2,FALSE),"") -> 1 | D38: 叶洁玲 | E38: =IF(F38="男","Male",IF(F38="女", "Female", "")) -> Female | F38: 女 | G38: 41 | H38: 2022-1-8 | I38: =IFERROR(DATEVALUE(H38),H38) -> 44569 | J38: =MAX(P38,R38,T38) -> 44568 | K38: =_xlfn.IFNA(VLOOKUP(D38,code!F:G,1,FALSE),"") | L38: 3 | M38: =Q38&"_"&S38&"_"&U38 -> 北京生物_北京生物_兰州生物 | N38: =VLOOKUP(M38,code!A:B,2,FALSE) -> PPP | O38: =VLOOKUP(M38,code!A:C,3,FALSE) -> N | P38: 44304 | Q38: 北京生物 | R38: 44351 | S38: 北京生物 | T38: 44568 | U38: 兰州生物
A39: 518 | B39: 杨宏 | C39: =IFERROR(VLOOKUP(B39,code!$F$1:$G$39,2,FALSE),"") -> 1 | D39: 黄嘉娣 | E39: =IF(F39="男","Male",IF(F39="女", "Female", "")) -> Female | F39: 女 | G39: 25 | H39: 2022-1-8 | I39: =IFERROR(DATEVALUE(H39),H39) -> 44569 | J39: =MAX(P39,R39,T39) -> 44573 | K39: =_xlfn.IFNA(VLOOKUP(D39,code!F:G,1,FALSE),"") | L39: 3 | M39: =Q39&"_"&S39&"_"&U39 -> 北京生物_北京生物_兰州生物 | N39: =VLOOKUP(M39,code!A:B,2,FALSE) -> PPP | O39: =VLOOKUP(M39,code!A:C,3,FALSE) -> N | P39: 44306 | Q39: 北京生物 | R39: 44349 | S39: 北京生物 | T39: 44573 | U39: 兰州生物
A40: 554 | B40: 杨宏 | C40: =IFERROR(VLOOKUP(B40,code!$F$1:$G$39,2,FALSE),"") -> 1 | D40: 伍瑞麒 | E40: =IF(F40="男","Male",IF(F40="女", "Female", "")) -> Male | F40: 男 | G40: 20 | H40: 2022-1-8 | I40: =IFERROR(DATEVALUE(H40),H40) -> 44569 | J40: =MAX(P40,R40,T40) -> 44563 | K40: =_xlfn.IFNA(VLOOKUP(D40,code!F:G,1,FALSE),"") | L40: 3 | M40: =Q40&"_"&S40&"_"&U40 -> 北京科兴中维_北京生物_兰州生物 | N40: =VLOOKUP(M40,code!A:B,2,FALSE) -> VPP | O40: =VLOOKUP(M40,code!A:C,3,FALSE) -> Y | P40: 44301 | Q40: 北京科兴中维 | R40: 44353 | S40: 北京生物 | T40: 44563 | U40: 兰州生物
...

Sheet code
A1: name | B1: code | C1: mix | F1: name | G1: code
A2: __成都生物 | B2: __P | C2: N | F2: 杨宏 | G2: 1 | H2: =VLOOKUP(F2,Sheet2!D:D,1,FALSE) -> #N/A
A3: __兰州生物 | B3: __P | C3: N | F3: 梁泳欣 | G3: 2 | H3: =VLOOKUP(F3,Sheet2!D:D,1,FALSE) -> 梁泳欣
A4: _北京生物_ | B4: _P_ | C4: N | F4: 焦贤英 | G4: 3 | H4: =VLOOKUP(F4,Sheet2!D:D,1,FALSE) -> #N/A
A5: _兰州生物_ | B5: _P_ | C5: N | F5: 梁桂雄 | G5: 4 | H5: =VLOOKUP(F5,Sheet2!D:D,1,FALSE) -> #N/A
A6: _北京科兴中维_ | B6: _V_ | C6: N | F6: 冯小如 | G6: 5 | H6: =VLOOKUP(F6,Sheet2!D:D,1,FALSE) -> #N/A
A7: _北京科兴中维_科兴（大连） | B7: _VV | C7: N | F7: 梁心悠 | G7: 6 | H7: =VLOOKUP(F7,Sheet2!D:D,1,FALSE) -> #N/A
A8: 康希诺生物__ | B8: A | C8: N | F8: 梁泽熙 | G8: 7 | H8: =VLOOKUP(F8,Sheet2!D:D,1,FALSE) -> #N/A
A9: 康希诺生物_康希诺生物_ | B9: AA | C9: N | F9: 闫冰 | G9: 8 | H9: =VLOOKUP(F9,Sheet2!D:D,1,FALSE) -> 闫冰
A10: 深圳康泰_深圳康泰_ | B10: KK | C10: N | F10: 莫月群 | G10: 9 | H10: =VLOOKUP(F10,Sheet2!D:D,1,FALSE) -> 莫月群
A11: 北京生物__ | B11: P | C11: N | F11: 谢米诺 | G11: 10 | H11: =VLOOKUP(F11,Sheet2!D:D,1,FALSE) -> 谢米诺
A12: 成都生物__ | B12: P | C12: N | F12: 李源 | G12: 11 | H12: =VLOOKUP(F12,Sheet2!D:D,1,FALSE) -> 李源
A13: 兰州生物__ | B13: P | C13: N | F13: 莫谏妹 | G13: 12 | H13: =VLOOKUP(F13,Sheet2!D:D,1,FALSE) -> #N/A
... A39: 成都生物__成都生物 | B39: PPP | C39: N | F39: 罗佳琦 | G39: 39 | H39: =VLOOKUP(F39,Sheet2!D:D,1,FALSE) -> 罗佳琦
A40: 成都生物_北京生物_兰州生物 | B40: PPP | C40: N
A41: 成都生物_兰州生物_兰州生物 | B41: PPP | C41: N
A42: 成都生物_长春生物_兰州生物 | B42: PPP | C42: N
A43: 兰州生物_北京生物_成都生物 | B43: PPP | C43: N
A44: 兰州生物_成都生物_兰州生物 | B44: PPP | C44: N
A45: 武汉生物_北京生物_成都生物 | B45: PPP | C45: N
A46: 武汉生物_北京生物_兰州生物 | B46: PPP | C46: N
A47: 武汉生物_武汉生物_兰州生物 | B47: PPP | C47: N
A48: 长春生物_北京生物_兰州生物 | B48: PPP | C48: N
A49: 长春生物_长春生物_兰州生物 | B49: PPP | C49: N
A50: 北京生物_北京生物_北京科兴 | B50: PPV | C50: Y
A51: 北京生物_北京生物_北京科兴中维 | B51: PPV | C51: Y
... A103: 安徽智飞_安徽智飞_安徽智飞 | B103: CCC | C103: N
A104: __

Sheet Sheet 1
A1: id | B1: age | C1: gender | D1: vaccine | E1: vaccine_type | F1: vaccine_mix | G1: outcome | H1: vaccinelastdate | I1: lastexposedate | J1: id_cases
A2: 1 | B2: 37 | C2: Female | D2: 1 | E2: PP | F2: N | G2: 0 | H2: 44559 | I2: 44569 | J2: 1
A3: 2 | B3: 9 | C3: Female | D3: 2 | E3: PP | F3: N | G3: 0 | H3: 44536 | I3: 44569 | J3: 1
A4: 3 | B4: 66 | C4: Female | D4: 2 | E4: VV | F4: N | G4: 0 | H4: 44458 | I4: 44569 | J4: 1
A5: 4 | B5: 40 | C5: Female | D5: 3 | E5: VVV | F5: N | G5: 0 | H5: 44525 | I5: 44569 | J5: 1
A6: 5 | B6: 43 | C6: Male | D6: 3 | E6: VVV | F6: N | G6: 0 | H6: 44528 | I6: 44569 | J6: 1
A7: 6 | B7: 4 | C7: Female | D7: 0 | E7: P | F7: N | G7: 0 | H7: 44564 | I7: 44574 | J7: 1
A8: 7 | B8: 32 | C8: Female | D8: 2 | E8: PP | F8: N | G8: 0 | H8: 44376 | I8: 44569 | J8: 1
A9: 8 | B9: 30 | C9: Female | D9: 3 | E9: PVV | F9: Y | G9: 0 | H9: 44530 | I9: 44569 | J9: 1
A10: 9 | B10: 17 | C10: Female | D10: 2 | E10: PP | F10: N | G10: 0 | H10: 44432 | I10: 44569 | J10: 1
A11: 10 | B11: 21 | C11: Female | D11: 2 | E11: PP | F11: N | G11: 0 | H11: 44347 | I11: 44569 | J11: 1
A12: 11 | B12: 31 | C12: Male | D12: 2 | E12: PPP | F12: N | G12: 0 | H12: 44564 | I12: 44569 | J12: 1
A13: 12 | B13: 49 | C13: Male | D13: 0 | G13: 0 | I13: 44569 | J13: 1
A14: 13 | B14: 8 | C14: Male | D14: 2 | E14: PP | F14: N | G14: 0 | H14: 44536 | I14: 44569 | J14: 1
A15: 14 | B15: 5 | C15: Male | D15: 1 | E15: P | F15: N | G15: 0 | H15: 44520 | I15: 44574 | J15: 1
A16: 15 | B16: 4 | C16: Female | D16: 0 | G16: 0 | I16: 44574 | J16: 1
A17: 16 | B17: 66 | C17: Male | D17: 2 | E17: VV | F17: N | G17: 0 | H17: 44437 | I17: 44569 | J17: 1
A18: 17 | B18: 67 | C18: Female | D18: 2 | E18: VV | F18: N | G18: 0 | H18: 44451 | I18: 44569 | J18: 1
A19: 18 | B19: 36 | C19: Female | D19: 3 | E19: VPP | F19: Y | G19: 0 | H19: 44540 | I19: 44569 | J19: 1
A20: 19 | B20: 21 | C20: Female | D20: 3 | E20: VVV | F20: N | G20: 0 | H20: 44534 | I20: 44571 | J20: 1
A21: 20 | B21: 73 | C21: Male | D21: 0 | G21: 0 | I21: 44569 | J21: 1
A22: 21 | B22: 8 | C22: Male | D22: 2 | E22: PP | F22: N | G22: 0 | H22: 44540 | I22: 44569 | J22: 1
A23: 22 | B23: 25 | C23: Male | D23: 2 | E23: A | F23: N | G23: 0 | H23: 44365 | I23: 44569 | J23: 1
A24: 23 | B24: 50 | C24: Male | D24: 2 | E24: VV | F24: N | G24: 0 | H24: 44452 | I24: 44569 | J24: 1
A25: 24 | B25: 65 | C25: Male | D25: 2 | E25: VV | F25: N | G25: 0 | H25: 44455 | I25: 44569 | J25: 1
A26: 25 | B26: 23 | C26: Male | D26: 2 | E26: VV | F26: N | G26: 0 | H26: 44432 | I26: 44569 | J26: 1
A27: 26 | B27: 28 | C27: Female | D27: 3 | E27: PPP | F27: N | G27: 0 | H27: 44535 | I27: 44569 | J27: 1
A28: 27 | B28: 46 | C28: Female | D28: 0 | G28: 0 | I28: 44569 | J28: 1
A29: 28 | B29: 71 | C29: Female | D29: 2 | E29: VV | F29: N | G29: 0 | H29: 44414 | I29: 44569 | J29: 1
A30: 29 | B30: 34 | C30: Female | D30: 1 | E30: PP | F30: N | G30: 0 | H30: 44574 | I30: 44569 | J30: 1
A31: 30 | B31: 40 | C31: Male | D31: 2 | E31: VV | F31: N | G31: 0 | H31: 44475 | I31: 44569 | J31: 1
A32: 31 | B32: 12 | C32: Male | D32: 2 | E32: PP | F32: N | G32: 0 | H32: 44531 | I32: 44569 | J32: 1
A33: 32 | B33: 73 | C33: Male | D33: 2 | E33: VV | F33: N | G33: 0 | H33: 44418 | I33: 44569 | J33: 1
A34: 33 | B34: 22 | C34: Male | D34: 1 | E34: VV | F34: N | G34: 0 | H34: 44569 | I34: 44569 | J34: 1
A35: 34 | B35: 69 | C35: Male | D35: 2 | E35: VV | F35: N | G35: 0 | H35: 44425 | I35: 44569 | J35: 1
A36: 35 | B36: 67 | C36: Male | D36: 2 | E36: PP | F36: N | G36: 0 | H36: 44541 | I36: 44569 | J36: 1
A37: 36 | B37: 37 | C37: Male | D37: 3 | E37: VVV | F37: N | G37: 0 | H37: 44534 | I37: 44569 | J37: 1
A38: 37 | B38: 21 | C38: Female | D38: 3 | E38: PPP | F38: N | G38: 0 | H38: 44531 | I38: 44569 | J38: 1
A39: 38 | B39: 40 | C39: Male | D39: 2 | E39: VP | F39: Y | G39: 0 | H39: 44430 | I39: 44569 | J39: 1
A40: 39 | B40: 48 | C40: Female | D40: 3 | E40: VVV | F40: N | G40: 0 | H40: 44534 | I40: 44569 | J40: 1
...

Sheet Sheet 1 (2)
A1: id | B1: name | D1: age | E1: gender | F1: vaccine | G1: vaccine_type | H1: vaccine_mix | I1: outcome | J1: vaccinelastdate | K1: lastexposedate | L1: id_cases
A2: 1 | B2: 顾小莉 | D2: 37 | E2: Female | F2: 1 | G2: PP | H2: N | I2: 0 | J2: 44559 | K2: 44569 | L2: 1
A3: 2 | B3: 郜嘉琪 | D3: 9 | E3: Female | F3: 2 | G3: PP | H3: N | I3: 0 | J3: 44536 | K3: 44569 | L3: 1
A4: 3 | B4: 董芝荣 | D4: 66 | E4: Female | F4: 2 | G4: VV | H4: N | I4: 0 | J4: 44458 | K4: 44569 | L4: 1
A5: 4 | B5: 袁琴 | D5: 40 | E5: Female | F5: 3 | G5: VVV | H5: N | I5: 0 | J5: 44525 | K5: 44569 | L5: 1
A6: 5 | B6: 张定国 | D6: 43 | E6: Male | F6: 3 | G6: VVV | H6: N | I6: 0 | J6: 44528 | K6: 44569 | L6: 1
A7: 6 | B7: 刘亦雯 | D7: 4 | E7: Female | F7: 0 | G7: P | H7: N | I7: 0 | J7: 44564 | K7: 44574 | L7: 1
A8: 783 | B8: 鲍玮琪 | D8: 8 | E8: Female | F8: 2 | G8: PP | H8: N | I8: 0 | J8: 44539 | K8: 44573 | L8: 11
A9: 8 | B9: 刘勋美 | D9: 30 | E9: Female | F9: 3 | G9: PVV | H9: Y | I9: 0 | J9: 44530 | K9: 44569 | L9: 1
A10: 9 | B10: 李丽珍 | D10: 17 | E10: Female | F10: 2 | G10: PP | H10: N | I10: 0 | J10: 44432 | K10: 44569 | L10: 1
A11: 10 | B11: 廖燕雯 | D11: 21 | E11: Female | F11: 2 | G11: PP | H11: N | I11: 0 | J11: 44347 | K11: 44569 | L11: 1
A12: 11 | B12: 朱红星 | D12: 31 | E12: Male | F12: 2 | G12: PPP | H12: N | I12: 0 | J12: 44564 | K12: 44569 | L12: 1
A13: 12 | B13: 唐祥培 | D13: 49 | E13: Male | F13: 0 | I13: 0 | K13: 44569 | L13: 1
A14: 13 | B14: 朱泽曦 | D14: 8 | E14: Male | F14: 2 | G14: PP | H14: N | I14: 0 | J14: 44536 | K14: 44569 | L14: 1
A15: 14 | B15: 陈彦君 | D15: 5 | E15: Male | F15: 1 | G15: P | H15: N | I15: 0 | J15: 44520 | K15: 44574 | L15: 1
A16: 15 | B16: 李雨阳 | D16: 4 | E16: Female | F16: 0 | I16: 0 | K16: 44574 | L16: 1
A17: 16 | B17: 曾群枝 | D17: 66 | E17: Male | F17: 2 | G17: VV | H17: N | I17: 0 | J17: 44437 | K17: 44569 | L17: 1
A18: 17 | B18: 林永球 | D18: 67 | E18: Female | F18: 2 | G18: VV | H18: N | I18: 0 | J18: 44451 | K18: 44569 | L18: 1
A19: 18 | B19: 任方琴 | D19: 36 | E19: Female | F19: 3 | G19: VPP | H19: Y | I19: 0 | J19: 44540 | K19: 44569 | L19: 1
A20: 19 | B20: 李文秀 | D20: 21 | E20: Female | F20: 3 | G20: VVV | H20: N | I20: 0 | J20: 44534 | K20: 44571 | L20: 1
A21: 20 | B21: 唐治平 | D21: 73 | E21: Male | F21: 0 | I21: 0 | K21: 44569 | L21: 1
A22: 21 | B22: 龙柏均 | D22: 8 | E22: Male | F22: 2 | G22: PP | H22: N | I22: 0 | J22: 44540 | K22: 44569 | L22: 1
A23: 22 | B23: 陈丽明 | D23: 25 | E23: Male | F23: 2 | G23: A | H23: N | I23: 0 | J23: 44365 | K23: 44569 | L23: 1
A24: 23 | B24: 许锦焕 | D24: 50 | E24: Male | F24: 2 | G24: VV | H24: N | I24: 0 | J24: 44452 | K24: 44569 | L24: 1
A25: 24 | B25: 滕才红 | D25: 65 | E25: Male | F25: 2 | G25: VV | H25: N | I25: 0 | J25: 44455 | K25: 44569 | L25: 1
A26: 25 | B26: 陶先朕 | D26: 23 | E26: Male | F26: 2 | G26: VV | H26: N | I26: 0 | J26: 44432 | K26: 44569 | L26: 1
A27: 26 | B27: 崔玮 | D27: 28 | E27: Female | F27: 3 | G27: PPP | H27: N | I27: 0 | J27: 44535 | K27: 44569 | L27: 1
A28: 27 | B28: 李芳芳 | D28: 46 | E28: Female | F28: 0 | I28: 0 | K28: 44569 | L28: 1
A29: 28 | B29: 林润连 | D29: 71 | E29: Female | F29: 2 | G29: VV | H29: N | I29: 0 | J29: 44414 | K29: 44569 | L29: 1
A30: 29 | B30: 黄巧玲 | D30: 34 | E30: Female | F30: 1 | G30: PP | H30: N | I30: 0 | J30: 44574 | K30: 44569 | L30: 1
A31: 30 | B31: 张发生 | D31: 40 | E31: Male | F31: 2 | G31: VV | H31: N | I31: 0 | J31: 44475 | K31: 44569 | L31: 1
A32: 31 | B32: 严博腾 | D32: 12 | E32: Male | F32: 2 | G32: PP | H32: N | I32: 0 | J32: 44531 | K32: 44569 | L32: 1
A33: 32 | B33: 曾润发 | D33: 73 | E33: Male | F33: 2 | G33: VV | H33: N | I33: 0 | J33: 44418 | K33: 44569 | L33: 1
A34: 33 | B34: 宋小贤 | D34: 22 | E34: Male | F34: 1 | G34: VV | H34: N | I34: 0 | J34: 44569 | K34: 44569 | L34: 1
A35: 34 | B35: 李子杰 | D35: 69 | E35: Male | F35: 2 | G35: VV | H35: N | I35: 0 | J35: 44425 | K35: 44569 | L35: 1
A36: 35 | B36: 潘永祥 | D36: 67 | E36: Male | F36: 2 | G36: PP | H36: N | I36: 0 | J36: 44541 | K36: 44569 | L36: 1
A37: 36 | B37: 钟剑泉 | D37: 37 | E37: Male | F37: 3 | G37: VVV | H37: N | I37: 0 | J37: 44534 | K37: 44569 | L37: 1
A38: 37 | B38: 余春华 | D38: 21 | E38: Female | F38: 3 | G38: PPP | H38: N | I38: 0 | J38: 44531 | K38: 44569 | L38: 1
A39: 38 | B39: 李泽红 | D39: 40 | E39: Male | F39: 2 | G39: VP | H39: Y | I39: 0 | J39: 44430 | K39: 44569 | L39: 1
A40: 39 | B40: 谭群英 | D40: 48 | E40: Female | F40: 3 | G40: VVV | H40: N | I40: 0 | J40: 44534 | K40: 44569 | L40: 1
...
